Traceback (most recent call last):
  File "/usr/local/lib/python3.9/site-packages/jupyter_cache/executors/utils.py", line 51, in single_nb_execution
    executenb(
  File "/usr/local/lib/python3.9/site-packages/nbclient/client.py", line 1093, in execute
    return NotebookClient(nb=nb, resources=resources, km=km, **kwargs).execute()
  File "/usr/local/lib/python3.9/site-packages/nbclient/util.py", line 84, in wrapped
    return just_run(coro(*args, **kwargs))
  File "/usr/local/lib/python3.9/site-packages/nbclient/util.py", line 62, in just_run
    return loop.run_until_complete(coro)
  File "/usr/local/Cellar/python@3.9/3.9.16/Frameworks/Python.framework/Versions/3.9/lib/python3.9/asyncio/base_events.py", line 647, in run_until_complete
    return future.result()
  File "/usr/local/lib/python3.9/site-packages/nbclient/client.py", line 559, in async_execute
    await self.async_execute_cell(
  File "/usr/local/lib/python3.9/site-packages/nbclient/client.py", line 854, in async_execute_cell
    self._check_raise_for_error(cell, exec_reply)
  File "/usr/local/lib/python3.9/site-packages/nbclient/client.py", line 756, in _check_raise_for_error
    raise CellExecutionError.from_cell_and_msg(cell, exec_reply_content)
nbclient.exceptions.CellExecutionError: An error occurred while executing the following cell:
------------------
x_vals = np.array([1, 1, 2])
y_vals = np.array([0, 3, 2])
z_vals = np.array([0,-2, 2])
p = np.array([x_vals, y_vals, z_vals])
lx=np.append(x_vals,x_vals[0]) #drawing the line between the last and first coord
ly=np.append(y_vals,y_vals[0])
lz=np.append(z_vals,z_vals[0])
ax = plt.figure().add_subplot(projection='3d')
ax.view_init(elev=20, azim=315, roll=0)
ax.plot(lx, ly, lz, 'ko', linestyle="--")
ax.plot(x_vals, y_vals, z_vals, 'ko')
ax.text(lx[0]-1, ly[0]+1, lz[0]+1, "A", c='k')
ax.text(lx[1]-1, ly[1]+1, lz[1]+1, "B", c='k')
ax.text(lx[2]-1, ly[2]+1, lz[2]+1, "C", c='k')
ax.set_xlabel('x')
ax.set_ylabel('y')
ax.set_zlabel('z')
ax.axes.set_xlim3d(left=-5, right=5) 
ax.axes.set_ylim3d(bottom=0, top=10) 
ax.axes.set_zlim3d(bottom=-5, top=5)
plt.gca().set_aspect('equal')
plt.show()
------------------

[0;31m---------------------------------------------------------------------------[0m
[0;31mTypeError[0m                                 Traceback (most recent call last)
[0;32m/var/folders/9y/379gbxjx3255qz9rg64kh7mm0000gn/T/ipykernel_34581/2098815996.py[0m in [0;36m<module>[0;34m[0m
[1;32m      7[0m [0mlz[0m[0;34m=[0m[0mnp[0m[0;34m.[0m[0mappend[0m[0;34m([0m[0mz_vals[0m[0;34m,[0m[0mz_vals[0m[0;34m[[0m[0;36m0[0m[0;34m][0m[0;34m)[0m[0;34m[0m[0;34m[0m[0m
[1;32m      8[0m [0max[0m [0;34m=[0m [0mplt[0m[0;34m.[0m[0mfigure[0m[0;34m([0m[0;34m)[0m[0;34m.[0m[0madd_subplot[0m[0;34m([0m[0mprojection[0m[0;34m=[0m[0;34m'3d'[0m[0;34m)[0m[0;34m[0m[0;34m[0m[0m
[0;32m----> 9[0;31m [0max[0m[0;34m.[0m[0mview_init[0m[0;34m([0m[0melev[0m[0;34m=[0m[0;36m20[0m[0;34m,[0m [0mazim[0m[0;34m=[0m[0;36m315[0m[0;34m,[0m [0mroll[0m[0;34m=[0m[0;36m0[0m[0;34m)[0m[0;34m[0m[0;34m[0m[0m
[0m[1;32m     10[0m [0max[0m[0;34m.[0m[0mplot[0m[0;34m([0m[0mlx[0m[0;34m,[0m [0mly[0m[0;34m,[0m [0mlz[0m[0;34m,[0m [0;34m'ko'[0m[0;34m,[0m [0mlinestyle[0m[0;34m=[0m[0;34m"--"[0m[0;34m)[0m[0;34m[0m[0;34m[0m[0m
[1;32m     11[0m [0max[0m[0;34m.[0m[0mplot[0m[0;34m([0m[0mx_vals[0m[0;34m,[0m [0my_vals[0m[0;34m,[0m [0mz_vals[0m[0;34m,[0m [0;34m'ko'[0m[0;34m)[0m[0;34m[0m[0;34m[0m[0m

[0;31mTypeError[0m: view_init() got an unexpected keyword argument 'roll'
TypeError: view_init() got an unexpected keyword argument 'roll'

